<?xml version="1.0" encoding="utf-8" ?>
<robot name="robot_arm_urdf">
    <!-- world link -->
    <link name="world" />
    <!-- ROBOTIC ARM JOINTS AND LINKS  -->
    <!-- base_joint     -->
    <joint name="base_joint" type="fixed">
        <parent link="world" />
        <child link="base_link" />
        <origin rpy="0 0 3.142" xyz="0.0 0.0 0.0" />
    </joint>
    <!-- base_link      -->
    <link name="base_link">
        <inertial>
            <origin xyz="4.1633E-17 0 0.073876" rpy="0 0 0" />
            <mass value="17.147" />
            <inertia ixx="0.192" ixy="-4.9423E-10" ixz="1.2752E-17" iyy="0.192" iyz="2.6417E-18" izz="0.29544" />
        </inertial>
        <visual>
            <origin xyz="0 0 0" rpy="0 0 0" />
            <geometry>
                <mesh filename="package://robot_arm_urdf/meshes/base_link.STL" />
            </geometry>
            <material name="">
                <color rgba="0.79216 0.81961 0.93333 1" />
            </material>
        </visual>
        <collision>
            <origin xyz="0 0 0" rpy="0 0 0" />
            <geometry>
                <mesh filename="package://robot_arm_urdf/meshes/base_link.STL" />
            </geometry>
        </collision>
    </link>
    <!-- link_1         -->
    <link name="link_1">
        <inertial>
            <origin xyz="-2.5757E-14 0.11047 -7.8988E-11" rpy="0 0 0" />
            <mass value="3.0905" />
            <inertia ixx="0.026302" ixy="-2.5267E-15" ixz="-1.4177E-12" iyy="0.019632" iyz="-7.4535E-12" izz="0.025388" />
        </inertial>
        <visual>
            <origin xyz="0 0 0" rpy="0 0 0" />
            <geometry>
                <mesh filename="package://robot_arm_urdf/meshes/link_1.STL" />
            </geometry>
            <material name="">
                <color rgba="1 1 1 1" />
            </material>
        </visual>
        <collision>
            <origin xyz="0 0 0" rpy="0 0 0" />
            <geometry>
                <mesh filename="package://robot_arm_urdf/meshes/link_1.STL" />
            </geometry>
        </collision>
    </link>
    <!-- joint_1 -->
    <joint name="joint_1" type="revolute">
        <origin xyz="0 0 0.2" rpy="1.5708 0 1.5708" />
        <parent link="base_link" />
        <child link="link_1" />
        <axis xyz="0 1 0" />
        <limit lower="0" upper="3.142" effort="300" velocity="3" />
    </joint>
    <!-- link_2         -->
    <link name="link_2">
        <inertial>
            <origin xyz="-1.1102E-16 0.16752 -2.498E-16" rpy="0 0 0" />
            <mass value="5.5867" />
            <inertia ixx="0.12632" ixy="8.4877E-17" ixz="7.8685E-19" iyy="0.011401" iyz="1.4432E-16" izz="0.12911" />
        </inertial>
        <visual>
            <origin xyz="0 0 0" rpy="0 0 0" />
            <geometry>
                <mesh filename="package://robot_arm_urdf/meshes/link_2.STL" />
            </geometry>
            <material name="">
                <color rgba="0.79216 0.81961 0.93333 1" />
            </material>
        </visual>
        <collision>
            <origin xyz="0 0 0" rpy="0 0 0" />
            <geometry>
                <mesh filename="package://robot_arm_urdf/meshes/link_2.STL" />
            </geometry>
        </collision>
    </link>
    <!-- joint_2 -->
    <joint name="joint_2" type="revolute">
        <origin xyz="0 0.205 0" rpy="0 0 0" />
        <parent link="link_1" />
        <child link="link_2" />
        <axis xyz="0 0 1" />
        <limit lower="-1.57" upper="1.57" effort="200" velocity="3" />
    </joint>
    <!-- link_3         -->
    <link name="link_3">
        <inertial>
            <origin xyz="-0.17893 0 -1.249E-16" rpy="0 0 0" />
            <mass value="2.8262" />
            <inertia ixx="0.0074041" ixy="-1.7927E-17" ixz="4.2672E-17" iyy="0.028552" iyz="-3.4736E-10" izz="0.025128" />
        </inertial>
        <visual>
            <origin xyz="0 0 0" rpy="0 0 0" />
            <geometry>
                <mesh filename="package://robot_arm_urdf/meshes/link_3.STL" />
            </geometry>
            <material name="">
                <color rgba="0.79216 0.81961 0.93333 1" />
            </material>
        </visual>
        <collision>
            <origin xyz="0 0 0" rpy="0 0 0" />
            <geometry>
                <mesh filename="package://robot_arm_urdf/meshes/link_3.STL" />
            </geometry>
        </collision>
    </link>
    <!-- joint_3 -->
    <joint name="joint_3" type="revolute">
        <origin xyz="0 0.4 0" rpy="0 0 0" />
        <parent link="link_2" />
        <child link="link_3" />
        <axis xyz="0 0 1" />
        <limit lower="-3.142" upper="0" effort="200" velocity="3" />
    </joint>
    <!-- link_4         -->
    <link name="link_4">
        <inertial>
            <origin xyz="-0.051672 -2.2204E-16 -1.1102E-16" rpy="0 0 0" />
            <mass value="1.8097" />
            <inertia ixx="0.0023112" ixy="-9.6437E-18" ixz="-9.9829E-19" iyy="0.0096102" iyz="1.3194E-19" izz="0.0093908" />
        </inertial>
        <visual>
            <origin xyz="0 0 0" rpy="0 0 0" />
            <geometry>
                <mesh filename="package://robot_arm_urdf/meshes/link_4.STL" />
            </geometry>
            <material name="">
                <color rgba="0.79216 0.81961 0.93333 1" />
            </material>
        </visual>
        <collision>
            <origin xyz="0 0 0" rpy="0 0 0" />
            <geometry>
                <mesh filename="package://robot_arm_urdf/meshes/link_4.STL" />
            </geometry>
        </collision>
    </link>
    <!-- joint_4 -->
    <joint name="joint_4" type="revolute">
        <origin xyz="-0.35 0 0" rpy="0 0 1.5708" />
        <parent link="link_3" />
        <child link="link_4" />
        <axis xyz="0 0 1" />
        <limit lower="-3.142" upper="0" effort="200" velocity="3" />
    </joint>
    <joint name="joint_5" type="revolute">
        <origin xyz="-0.188 0 0" rpy="0 -1.59 0" />
        <parent link="link_4" />
        <child link="gripper_base_link" />
        <axis xyz="0 0 1" />
        <limit lower="0" upper="3.142" effort="200" velocity="3" />
    </joint>
    <!-- GRIPPER  -->
    <!-- gripper_base_link         -->
    <link name="gripper_base_link">
        <visual>
            <geometry>
                <mesh filename="package://robot_arm_urdf/meshes/gripper_base_link.STL" scale="0.001 0.001 0.001" />
            </geometry>
            <material name="">
                <color rgba="0.79216 0.81961 0.93333 1" />
            </material>
        </visual>
        <collision>
            <geometry>
                <mesh filename="package://robot_arm_urdf/meshes/gripper_base_link.STL" scale="0.001 0.001 0.001" />
            </geometry>
        </collision>
        <inertial>
            <mass value="0.83416" />
            <origin xyz="0.0 0.0 0.0" rpy="0 0 0" />
            <inertia ixx="0.0013016" ixy="-6.9374e-07" ixz="5.9848e-07" iyx="0.000000" iyy="0.00049972" iyz="2.0244E-07" izx="0.000000" izy="0.000000" izz="0.001498" />
        </inertial>
    </link>
    <gazebo reference="gripper_base_link">
        <implicitSpringDamper>1</implicitSpringDamper>
        <mu1>100000</mu1>
        <mu2>100000</mu2>
        <kp>100000000.0</kp>
        <kd>1.0</kd>
        <plugin name="gazebo_ros_control">
            <robotNamespace>/</robotNamespace>
        </plugin>
    </gazebo>
    <!-- gripper_finger1_joint         -->
    <joint name="gripper_finger1_joint" type="revolute">
        <parent link="gripper_base_link" />
        <child link="gripper_finger1_knuckle_link" />
        <axis xyz="0 -1 0" />
        <origin rpy="0.0 0.0 3.14" xyz="-0.016 0 0.10586" />
        <limit lower="0.0" upper="0.6524" velocity="2.0" effort="1000" />
    </joint>
    <!-- gripper_finger2_joint         -->
    <joint name="gripper_finger2_joint" type="revolute">
        <parent link="gripper_base_link" />
        <child link="gripper_finger2_knuckle_link" />
        <axis xyz="0 -1 0" />
        <origin rpy="0.0 0.0 0.0" xyz="0.016  0 0.10586 " />
        <limit lower="-3.14" upper="3.14" velocity="100.0" effort="1000" />
        <mimic joint="gripper_finger1_joint" />
    </joint>
    <!-- gripper_finger1_knuckle_link         -->
    <link name="gripper_finger1_knuckle_link">
        <visual>
            <geometry>
                <mesh filename="package://robot_arm_urdf/meshes/gripper_crank_Link.STL" scale="0.001 0.001 0.001" />
            </geometry>
            <material name="">
                <color rgba="0.79216 0.81961 0.93333 1" />
            </material>
        </visual>
        <collision>
            <geometry>
                <mesh filename="package://robot_arm_urdf/meshes/gripper_crank_Link.STL" scale="0.001 0.001 0.001" />
            </geometry>
        </collision>
        <inertial>
            <mass value="0.011111" />
            <origin xyz="0.0 0.0 0.0" rpy="0 0 0" />
            <inertia ixx="3.88172e-06" ixy="-2.29456e-13" ixz="8.33e-07" iyx="0.000000" iyy="1.92174e-06" iyz="2.04435e-13" izx="0.000000" izy="0.000000" izz="4.32374e-06" />
        </inertial>
    </link>
    <gazebo reference="gripper_finger1_knuckle_link">
        <implicitSpringDamper>1</implicitSpringDamper>
        <mu1>100000</mu1>
        <mu2>100000</mu2>
        <kp>100000000.0</kp>
        <kd>1.0</kd>
    </gazebo>
    <!-- gripper_finger2_knuckle_link         -->
    <link name="gripper_finger2_knuckle_link">
        <visual>
            <geometry>
                <mesh filename="package://robot_arm_urdf/meshes/gripper_crank_Link.STL" scale="0.001 0.001 0.001" />
            </geometry>
            <material name="">
                <color rgba="0.79216 0.81961 0.93333 1" />
            </material>
        </visual>
        <collision>
            <geometry>
                <mesh filename="package://robot_arm_urdf/meshes/gripper_crank_Link.STL" scale="0.001 0.001 0.001" />
            </geometry>
        </collision>
        <inertial>
            <mass value="0.011111" />
            <origin xyz="0.0 0.0 0.0" rpy="0 0 0" />
            <inertia ixx="3.88172e-06" ixy="-2.29456e-13" ixz="8.33e-07" iyx="0.000000" iyy="1.92174e-06" iyz="2.04435e-13" izx="0.000000" izy="0.000000" izz="4.32374e-06" />
        </inertial>
    </link>
    <gazebo reference="gripper_finger2_knuckle_link">
        <implicitSpringDamper>1</implicitSpringDamper>
        <mu1>100000</mu1>
        <mu2>100000</mu2>
        <kp>100000000.0</kp>
        <kd>1.0</kd>
    </gazebo>
    <!-- gripper_finger1_finger_joint -->
    <joint name="gripper_finger1_finger_joint" type="continuous">
        <parent link="gripper_finger1_knuckle_link" />
        <child link="gripper_finger1_finger_link" />
        <axis xyz="0 -1 0" />
        <origin xyz="0.0292080077784 0.0 -0.0227132622407" rpy="0 0 0" />
        <limit lower="-3.14" upper="3.14" velocity="100.0" effort="0.1" />
        <mimic joint="gripper_finger1_joint" multiplier="0.4563942" offset="0" />
    </joint>
    <!-- gripper_finger2_finger_joint -->
    <joint name="gripper_finger2_finger_joint" type="continuous">
        <parent link="gripper_finger2_knuckle_link" />
        <child link="gripper_finger2_finger_link" />
        <axis xyz="0 -1 0" />
        <origin xyz="0.0292080077784 0.0 -0.0227132622407" rpy="0 0 0" />
        <limit lower="-3.14" upper="3.14" velocity="100.0" effort="0.1" />
        <mimic joint="gripper_finger1_joint" multiplier="0.4563942" offset="0" />
    </joint>
    <link name="gripper_finger1_finger_link">
        <visual>
            <geometry>
                <mesh filename="package://robot_arm_urdf/meshes/gripper_rod_Link.STL" scale="0.001 0.001 0.001" />
            </geometry>
            <material name="">
                <color rgba="0.79216 0.81961 0.93333 1" />
            </material>
        </visual>
        <collision>
            <geometry>
                <mesh filename="package://robot_arm_urdf/meshes/gripper_rod_Link.STL" scale="0.001 0.001 0.001" />
            </geometry>
        </collision>
        <inertial>
            <mass value="0.0222871" />
            <origin xyz="0.0 0.0 0.0" rpy="0 0 0" />
            <inertia ixx="8.72836e-06" ixy="7.0843e-15" ixz="-2.18833e-06" iyx="-0.000002" iyy="7.26157e-06" iyz="7.6579e-15" izx="0.000000" izy="0.000000" izz="3.3425e-06" />
        </inertial>
    </link>
    <gazebo reference="gripper_finger1_finger_link">
        <implicitSpringDamper>1</implicitSpringDamper>
        <mu1>100000</mu1>
        <mu2>100000</mu2>
        <kp>100000000.0</kp>
        <kd>1.0</kd>
    </gazebo>
    <link name="gripper_finger2_finger_link">
        <visual>
            <geometry>
                <mesh filename="package://robot_arm_urdf/meshes/gripper_rod_Link.STL" scale="0.001 0.001 0.001" />
            </geometry>
            <material name="">
                <color rgba="0.79216 0.81961 0.93333 1" />
            </material>
        </visual>
        <collision>
            <geometry>
                <mesh filename="package://robot_arm_urdf/meshes/gripper_rod_Link.STL" scale="0.001 0.001 0.001" />
            </geometry>
        </collision>
        <inertial>
            <mass value="0.0222871" />
            <origin xyz="0.0 0.0 0.0" rpy="0 0 0" />
            <inertia ixx="8.72836e-06" ixy="7.0843e-15" ixz="-2.18833e-06" iyx="-0.000002" iyy="7.26157e-06" iyz="7.6579e-15" izx="0.000000" izy="0.000000" izz="3.3425e-06" />
        </inertial>
    </link>
    <gazebo reference="gripper_finger2_finger_link">
        <implicitSpringDamper>1</implicitSpringDamper>
        <mu1>100000</mu1>
        <mu2>100000</mu2>
        <kp>100000000.0</kp>
        <kd>1.0</kd>
    </gazebo>
    <joint name="gripper_finger1_inner_knuckle_joint" type="continuous">
        <parent link="gripper_base_link" />
        <child link="gripper_finger1_inner_knuckle_link" />
        <axis xyz="0 -1 0" />
        <origin rpy="0.0 0.0 3.14" xyz="-0.016 0 0.10586" />
        <limit lower="-3.14" upper="3.14" velocity="100.0" effort="0.1" />
        <mimic joint="gripper_finger1_joint" multiplier="1.49462955" offset="0" />
    </joint>
    <joint name="gripper_finger2_inner_knuckle_joint" type="continuous">
        <parent link="gripper_base_link" />
        <child link="gripper_finger2_inner_knuckle_link" />
        <axis xyz="0 -1 0" />
        <origin rpy="0.0 0.0 0.0" xyz="0.016 0 0.10586" />
        <limit lower="-3.14" upper="3.14" velocity="100.0" effort="0.1" />
        <mimic joint="gripper_finger1_joint" multiplier="1.49462955" offset="0" />
    </joint>
    <link name="gripper_finger1_inner_knuckle_link">
        <visual>
            <geometry>
                <mesh filename="package://robot_arm_urdf/meshes/gripper_proximal_phalanx_Link.STL" scale="0.001 0.001 0.001" />
            </geometry>
            <material name="">
                <color rgba="0.79216 0.81961 0.93333 1" />
            </material>
        </visual>
        <collision>
            <geometry>
                <mesh filename="package://robot_arm_urdf/meshes/gripper_proximal_phalanx_Link.STL" scale="0.001 0.001 0.001" />
            </geometry>
        </collision>
        <inertial>
            <mass value="0.0318004" />
            <origin xyz="0.0 0.0 0.0" rpy="0 0 0" />
            <inertia ixx="1.39848e-05" ixy="-9.54763e-15" ixz="-5.01422e-06" iyx="0.000000" iyy="1.04943e-05" iyz="8.94585e-16" izx="0.000000" izy="0.000000" izz="1.36183e-05" />
        </inertial>
    </link>
    <gazebo reference="gripper_finger1_inner_knuckle_link">
        <implicitSpringDamper>1</implicitSpringDamper>
        <mu1>100000</mu1>
        <mu2>100000</mu2>
        <kp>100000000.0</kp>
        <kd>1.0</kd>
    </gazebo>
    <link name="gripper_finger2_inner_knuckle_link">
        <visual>
            <geometry>
                <mesh filename="package://robot_arm_urdf/meshes/gripper_proximal_phalanx_Link.STL" scale="0.001 0.001 0.001" />
            </geometry>
            <material name="">
                <color rgba="0.79216 0.81961 0.93333 1" />
            </material>
        </visual>
        <collision>
            <geometry>
                <mesh filename="package://robot_arm_urdf/meshes/gripper_proximal_phalanx_Link.STL" scale="0.001 0.001 0.001" />
            </geometry>
        </collision>
        <inertial>
            <mass value="0.0318004" />
            <origin xyz="0.0 0.0 0.0" rpy="0 0 0" />
            <inertia ixx="1.39848e-05" ixy="-9.54763e-15" ixz="-5.01422e-06" iyx="0.000000" iyy="1.04943e-05" iyz="8.94585e-16" izx="0.000000" izy="0.000000" izz="1.36183e-05" />
        </inertial>
    </link>
    <gazebo reference="gripper_finger2_inner_knuckle_link">
        <implicitSpringDamper>1</implicitSpringDamper>
        <mu1>100000</mu1>
        <mu2>100000</mu2>
        <kp>100000000.0</kp>
        <kd>1.0</kd>
    </gazebo>
    <joint name="gripper_finger1_finger_tip_joint" type="continuous">
        <parent link="gripper_finger1_inner_knuckle_link" />
        <child link="gripper_finger1_finger_tip_link" />
        <axis xyz="0 1 0" />
        <origin xyz="0.0394969463769 0.0 0.0382752038125 " rpy="0.0 0.0 0.0" />
        <limit lower="-3.14" upper="3.14" velocity="100.0" effort="0.1" />
        <mimic joint="gripper_finger1_joint" multiplier="1.49462955" />
    </joint>
    <joint name="gripper_finger2_finger_tip_joint" type="continuous">
        <parent link="gripper_finger2_inner_knuckle_link" />
        <child link="gripper_finger2_finger_tip_link" />
        <axis xyz="0 1 0" />
        <origin rpy="0.0 0.0 0.0" xyz="0.0394969463769  0.0 0.0382752038125  " />
        <limit lower="-3.14" upper="3.14" velocity="100.0" effort="0.1" />
        <mimic joint="gripper_finger1_joint" multiplier="1.49462955" />
    </joint>
    <link name="gripper_finger1_finger_tip_link">
        <visual>
            <geometry>
                <mesh filename="package://robot_arm_urdf/meshes/gripper_distal_phalanx_Link.STL" scale="0.001 0.001 0.001" />
            </geometry>
            <material name="">
                <color rgba="0.79216 0.81961 0.93333 1" />
            </material>
        </visual>
        <collision>
            <geometry>
                <mesh filename="package://robot_arm_urdf/meshes/gripper_distal_phalanx_Link.STL" scale="0.001 0.001 0.001" />
            </geometry>
        </collision>
        <inertial>
            <mass value="0.0124305" />
            <origin xyz="0.0 0.0 0.0" rpy="0 0 0" />
            <inertia ixx="2.84217e-06" ixy="-2.48048e-15" ixz="8.24539e-07" iyx="0.000000" iyy="3.03961e-06" iyz="2.16427e-13" izx="0.000000" izy="0.000000" izz="1.11815e-06" />
        </inertial>
    </link>
    <gazebo reference="gripper_finger1_finger_tip_link">
        <implicitSpringDamper>1</implicitSpringDamper>
        <mu1>100000</mu1>
        <mu2>100000</mu2>
        <kp>100000000.0</kp>
        <kd>1.0</kd>
    </gazebo>
    <link name="gripper_finger2_finger_tip_link">
        <visual>
            <geometry>
                <mesh filename="package://robot_arm_urdf/meshes/gripper_distal_phalanx_Link.STL" scale="0.001 0.001 0.001" />
            </geometry>
            <material name="">
                <color rgba="0.79216 0.81961 0.93333 1" />
            </material>
        </visual>
        <collision>
            <geometry>
                <mesh filename="package://robot_arm_urdf/meshes/gripper_distal_phalanx_Link.STL" scale="0.001 0.001 0.001" />
            </geometry>
        </collision>
        <inertial>
            <mass value="0.0124305" />
            <origin xyz="0.0 0.0 0.0" rpy="0 0 0" />
            <inertia ixx="2.84217e-06" ixy="-2.48048e-15" ixz="8.24539e-07" iyx="0.000000" iyy="3.03961e-06" iyz="2.16427e-13" izx="0.000000" izy="0.000000" izz="1.11815e-06" />
        </inertial>
    </link>
    <gazebo reference="gripper_finger2_finger_tip_link">
        <implicitSpringDamper>1</implicitSpringDamper>
        <mu1>100000</mu1>
        <mu2>100000</mu2>
        <kp>100000000.0</kp>
        <kd>1.0</kd>
    </gazebo>
    <!-- TRANSMISSION Tag -->
    <transmission name="link_1_trans">
        <type>transmission_interface/SimpleTransmission</type>
        <joint name="joint_1">
            <hardwareInterface>hardware_interface/PositionJointInterface</hardwareInterface>
        </joint>
        <actuator name="link_1_motor">
            <hardwareInterface>hardware_interface/PositionJointInterface</hardwareInterface>
            <mechanicalReduction>1</mechanicalReduction>
        </actuator>
    </transmission>
    <transmission name="link_2_trans">
        <type>transmission_interface/SimpleTransmission</type>
        <joint name="joint_2">
            <hardwareInterface>hardware_interface/PositionJointInterface</hardwareInterface>
        </joint>
        <actuator name="link_2_motor">
            <hardwareInterface>hardware_interface/PositionJointInterface</hardwareInterface>
            <mechanicalReduction>1</mechanicalReduction>
        </actuator>
    </transmission>
    <transmission name="link_3_trans">
        <type>transmission_interface/SimpleTransmission</type>
        <joint name="joint_3">
            <hardwareInterface>hardware_interface/PositionJointInterface</hardwareInterface>
        </joint>
        <actuator name="link_3_motor">
            <hardwareInterface>hardware_interface/PositionJointInterface</hardwareInterface>
            <mechanicalReduction>1</mechanicalReduction>
        </actuator>
    </transmission>
    <transmission name="link_4_trans">
        <type>transmission_interface/SimpleTransmission</type>
        <joint name="joint_4">
            <hardwareInterface>hardware_interface/PositionJointInterface</hardwareInterface>
        </joint>
        <actuator name="link_4_motor">
            <hardwareInterface>hardware_interface/PositionJointInterface</hardwareInterface>
            <mechanicalReduction>1</mechanicalReduction>
        </actuator>
    </transmission>
    <transmission name="link_5_trans">
        <type>transmission_interface/SimpleTransmission</type>
        <joint name="joint_5">
            <hardwareInterface>hardware_interface/PositionJointInterface</hardwareInterface>
        </joint>
        <actuator name="link_5_motor">
            <hardwareInterface>hardware_interface/PositionJointInterface</hardwareInterface>
            <mechanicalReduction>1</mechanicalReduction>
        </actuator>
    </transmission>
    <transmission name="gripper_finger1_trans">
        <type>transmission_interface/SimpleTransmission</type>
        <joint name="gripper_finger1_joint">
            <hardwareInterface>hardware_interface/EffortJointInterface</hardwareInterface>
        </joint>
        <actuator name="gripper_finger1_motor">
            <mechanicalReduction>1</mechanicalReduction>
            <hardwareInterface>hardware_interface/EffortJointInterface</hardwareInterface>
        </actuator>
    </transmission>
    <!-- GAZEBO Tag -->
    <gazebo>
        <plugin name="control" filename="libgazebo_ros_control.so">
            <robotNamespace>/</robotNamespace>
        </plugin>
    </gazebo>
    <gazebo reference="link_1">
        <selfCollide>true</selfCollide>
    </gazebo>
    <gazebo reference="link_2">
        <selfCollide>true</selfCollide>
    </gazebo>
    <gazebo reference="link_3">
        <selfCollide>true</selfCollide>
    </gazebo>
    <gazebo reference="link_4">
        <selfCollide>true</selfCollide>
    </gazebo>
    <gazebo reference="link_5">
        <selfCollide>true</selfCollide>
    </gazebo>
    <gazebo>
        <plugin filename="libroboticsgroup_gazebo_mimic_joint_plugin.so" name="mimic_dh_robotics_ag95_1">
            <joint>gripper_finger1_joint</joint>
            <mimicJoint>gripper_finger2_joint</mimicJoint>
            <multiplier>1.0</multiplier>
            <offset>0.0</offset>
        </plugin>
        <plugin filename="libroboticsgroup_gazebo_mimic_joint_plugin.so" name="mimic_dh_robotics_ag95_2">
            <joint>gripper_finger1_joint</joint>
            <mimicJoint>gripper_finger2_inner_knuckle_joint</mimicJoint>
            <multiplier>1.49462955</multiplier>
            <offset>0.0</offset>
        </plugin>
        <plugin filename="libroboticsgroup_gazebo_mimic_joint_plugin.so" name="mimic_dh_robotics_ag95_3">
            <joint>gripper_finger1_joint</joint>
            <mimicJoint>gripper_finger1_inner_knuckle_joint</mimicJoint>
            <multiplier>1.49462955</multiplier>
            <offset>0.0</offset>
        </plugin>
        <plugin filename="libroboticsgroup_gazebo_mimic_joint_plugin.so" name="mimic_dh_robotics_ag95_4">
            <joint>gripper_finger1_joint</joint>
            <mimicJoint>gripper_finger1_finger_tip_joint</mimicJoint>
            <multiplier>1.49462955</multiplier>
            <offset>0.0</offset>
        </plugin>
        <plugin filename="libroboticsgroup_gazebo_mimic_joint_plugin.so" name="mimic_dh_robotics_ag95_5">
            <joint>gripper_finger1_joint</joint>
            <mimicJoint>gripper_finger2_finger_tip_joint</mimicJoint>
            <multiplier>1.49462955</multiplier>
            <offset>0.0</offset>
        </plugin>
        <plugin filename="libroboticsgroup_gazebo_mimic_joint_plugin.so" name="mimic_dh_robotics_ag95_6">
            <joint>gripper_finger1_joint</joint>
            <mimicJoint>gripper_finger1_finger_joint</mimicJoint>
            <multiplier>0.4563942</multiplier>
            <offset>0.0</offset>
        </plugin>
        <plugin filename="libroboticsgroup_gazebo_mimic_joint_plugin.so" name="mimic_dh_robotics_ag95_7">
            <joint>gripper_finger1_joint</joint>
            <mimicJoint>gripper_finger2_finger_joint</mimicJoint>
            <multiplier>0.4563942</multiplier>
            <offset>0.0</offset>
        </plugin>
    </gazebo>
    <transmission name="trans_gripper_finger2_joint">
        <type>transmission_interface/SimpleTransmission</type>
        <joint name="gripper_finger2_joint">
            <hardwareInterface>hardware_interface/EffortJointInterface</hardwareInterface>
        </joint>
        <actuator name="gripper_finger2_joint_motor">
            <hardwareInterface>hardware_interface/EffortJointInterface</hardwareInterface>
            <mechanicalReduction>1</mechanicalReduction>
        </actuator>
    </transmission>
    <transmission name="trans_gripper_finger1_finger_joint">
        <type>transmission_interface/SimpleTransmission</type>
        <joint name="gripper_finger1_finger_joint">
            <hardwareInterface>hardware_interface/EffortJointInterface</hardwareInterface>
        </joint>
        <actuator name="gripper_finger1_finger_joint_motor">
            <hardwareInterface>hardware_interface/EffortJointInterface</hardwareInterface>
            <mechanicalReduction>1</mechanicalReduction>
        </actuator>
    </transmission>
    <transmission name="trans_gripper_finger2_finger_joint">
        <type>transmission_interface/SimpleTransmission</type>
        <joint name="gripper_finger2_finger_joint">
            <hardwareInterface>hardware_interface/EffortJointInterface</hardwareInterface>
        </joint>
        <actuator name="gripper_finger2_finger_joint_motor">
            <hardwareInterface>hardware_interface/EffortJointInterface</hardwareInterface>
            <mechanicalReduction>1</mechanicalReduction>
        </actuator>
    </transmission>
    <transmission name="trans_gripper_finger1_inner_knuckle_joint">
        <type>transmission_interface/SimpleTransmission</type>
        <joint name="gripper_finger1_inner_knuckle_joint">
            <hardwareInterface>hardware_interface/EffortJointInterface</hardwareInterface>
        </joint>
        <actuator name="gripper_finger1_inner_knuckle_joint_motor">
            <hardwareInterface>hardware_interface/EffortJointInterface</hardwareInterface>
            <mechanicalReduction>1</mechanicalReduction>
        </actuator>
    </transmission>
    <transmission name="trans_gripper_finger2_inner_knuckle_joint">
        <type>transmission_interface/SimpleTransmission</type>
        <joint name="gripper_finger2_inner_knuckle_joint">
            <hardwareInterface>hardware_interface/EffortJointInterface</hardwareInterface>
        </joint>
        <actuator name="gripper_finger2_inner_knuckle_joint_motor">
            <hardwareInterface>hardware_interface/EffortJointInterface</hardwareInterface>
            <mechanicalReduction>1</mechanicalReduction>
        </actuator>
    </transmission>
    <transmission name="trans_gripper_finger1_finger_tip_joint">
        <type>transmission_interface/SimpleTransmission</type>
        <joint name="gripper_finger1_finger_tip_joint">
            <hardwareInterface>hardware_interface/EffortJointInterface</hardwareInterface>
        </joint>
        <actuator name="gripper_finger1_finger_tip_joint_motor">
            <hardwareInterface>hardware_interface/EffortJointInterface</hardwareInterface>
            <mechanicalReduction>1</mechanicalReduction>
        </actuator>
    </transmission>
    <transmission name="trans_gripper_finger2_finger_tip_joint">
        <type>transmission_interface/SimpleTransmission</type>
        <joint name="gripper_finger2_finger_tip_joint">
            <hardwareInterface>hardware_interface/EffortJointInterface</hardwareInterface>
        </joint>
        <actuator name="gripper_finger2_finger_tip_joint_motor">
            <hardwareInterface>hardware_interface/EffortJointInterface</hardwareInterface>
            <mechanicalReduction>1</mechanicalReduction>
        </actuator>
    </transmission>
</robot>

